-------------------------------------------------------------------------------
Test set: TestSuite
-------------------------------------------------------------------------------
Tests run: 6, Failures: 2, Errors: 0, Skipped: 0, Time elapsed: 52.18 s <<< FAILURE! -- in TestSuite
vinayakshettypractice.tests.ErrorValidationsTest.ProductErrorValidation -- Time elapsed: 11.58 s <<< FAILURE!
java.lang.AssertionError: expected [true] but found [false]
	at org.testng.Assert.fail(Assert.java:94)
	at org.testng.Assert.failNotEquals(Assert.java:496)
	at org.testng.Assert.assertTrue(Assert.java:42)
	at org.testng.Assert.assertTrue(Assert.java:52)
	at vinayakshettypractice.tests.ErrorValidationsTest.ProductErrorValidation(ErrorValidationsTest.java:55)
	at java.base/jdk.internal.reflect.DirectMethodHandleAccessor.invoke(DirectMethodHandleAccessor.java:104)
	at java.base/java.lang.reflect.Method.invoke(Method.java:578)
	at org.testng.internal.MethodInvocationHelper.invokeMethod(MethodInvocationHelper.java:85)
	at org.testng.internal.Invoker.invokeMethod(Invoker.java:659)
	at org.testng.internal.Invoker.invokeTestMethod(Invoker.java:845)
	at org.testng.internal.Invoker.invokeTestMethods(Invoker.java:1153)
	at org.testng.internal.TestMethodWorker.invokeTestMethods(TestMethodWorker.java:125)
	at org.testng.internal.TestMethodWorker.run(TestMethodWorker.java:108)
	at org.testng.TestRunner.privateRun(TestRunner.java:771)
	at org.testng.TestRunner.run(TestRunner.java:621)
	at org.testng.SuiteRunner.runTest(SuiteRunner.java:357)
	at org.testng.SuiteRunner.access$000(SuiteRunner.java:38)
	at org.testng.SuiteRunner$SuiteWorker.run(SuiteRunner.java:391)
	at org.testng.internal.thread.ThreadUtil$2.call(ThreadUtil.java:64)
	at java.base/java.util.concurrent.FutureTask.run(FutureTask.java:317)
	at java.base/java.util.concurrent.ThreadPoolExecutor.runWorker(ThreadPoolExecutor.java:1144)
	at java.base/java.util.concurrent.ThreadPoolExecutor$Worker.run(ThreadPoolExecutor.java:642)
	at java.base/java.lang.Thread.run(Thread.java:1589)

vinayakshettypractice.tests.ErrorValidationsTest.ProductErrorValidation -- Time elapsed: 21.46 s <<< FAILURE!
java.lang.AssertionError: expected [true] but found [false]
	at org.testng.Assert.fail(Assert.java:94)
	at org.testng.Assert.failNotEquals(Assert.java:496)
	at org.testng.Assert.assertTrue(Assert.java:42)
	at org.testng.Assert.assertTrue(Assert.java:52)
	at vinayakshettypractice.tests.ErrorValidationsTest.ProductErrorValidation(ErrorValidationsTest.java:55)
	at java.base/jdk.internal.reflect.DirectMethodHandleAccessor.invoke(DirectMethodHandleAccessor.java:104)
	at java.base/java.lang.reflect.Method.invoke(Method.java:578)
	at org.testng.internal.MethodInvocationHelper.invokeMethod(MethodInvocationHelper.java:85)
	at org.testng.internal.Invoker.invokeMethod(Invoker.java:659)
	at org.testng.internal.Invoker.retryFailed(Invoker.java:991)
	at org.testng.internal.Invoker.invokeTestMethods(Invoker.java:1171)
	at org.testng.internal.TestMethodWorker.invokeTestMethods(TestMethodWorker.java:125)
	at org.testng.internal.TestMethodWorker.run(TestMethodWorker.java:108)
	at org.testng.TestRunner.privateRun(TestRunner.java:771)
	at org.testng.TestRunner.run(TestRunner.java:621)
	at org.testng.SuiteRunner.runTest(SuiteRunner.java:357)
	at org.testng.SuiteRunner.access$000(SuiteRunner.java:38)
	at org.testng.SuiteRunner$SuiteWorker.run(SuiteRunner.java:391)
	at org.testng.internal.thread.ThreadUtil$2.call(ThreadUtil.java:64)
	at java.base/java.util.concurrent.FutureTask.run(FutureTask.java:317)
	at java.base/java.util.concurrent.ThreadPoolExecutor.runWorker(ThreadPoolExecutor.java:1144)
	at java.base/java.util.concurrent.ThreadPoolExecutor$Worker.run(ThreadPoolExecutor.java:642)
	at java.base/java.lang.Thread.run(Thread.java:1589)

