<?xml version="1.0" encoding="UTF-8"?>
<testng-results retried="2" ignored="0" total="7" passed="1" failed="3" skipped="1">
  <reporter-output>
  </reporter-output>
  <suite started-at="2024-02-07T19:34:20 IST" name="Suite" finished-at="2024-02-07T19:35:11 IST" duration-ms="51037">
    <groups>
      <group name="ErrorHandling">
        <method signature="ErrorValidationsTest.LoginErrorValidation()[pri:0, instance:vinayakshettypractice.tests.ErrorValidationsTest@333d4a8c]" name="LoginErrorValidation" class="vinayakshettypractice.tests.ErrorValidationsTest"/>
      </group> <!-- ErrorHandling -->
      <group name="Purchase">
        <method signature="SubmitOrderTest.submitOrder(java.util.HashMap)[pri:0, instance:vinayakshettypractice.tests.SubmitOrderTest@221a3fa4]" name="submitOrder" class="vinayakshettypractice.tests.SubmitOrderTest"/>
      </group> <!-- Purchase -->
    </groups>
    <test started-at="2024-02-07T19:34:20 IST" name="Submit Order Test" finished-at="2024-02-07T19:35:00 IST" duration-ms="40661">
      <class name="vinayakshettypractice.tests.SubmitOrderTest">
        <test-method is-config="true" signature="launchApplication()[pri:0, instance:vinayakshettypractice.tests.SubmitOrderTest@221a3fa4]" started-at="2024-02-07T19:34:20 IST" name="launchApplication" finished-at="2024-02-07T19:34:26 IST" duration-ms="6218" status="PASS">
          <reporter-output>
          </reporter-output>
        </test-method> <!-- launchApplication -->
        <test-method signature="submitOrder(java.util.HashMap)[pri:0, instance:vinayakshettypractice.tests.SubmitOrderTest@221a3fa4]" started-at="2024-02-07T19:34:26 IST" name="submitOrder" data-provider="getData" finished-at="2024-02-07T19:34:41 IST" duration-ms="15176" status="FAIL">
          <params>
            <param index="0">
              <value>
                <![CDATA[{password=Vinayak@12, email=vinayak01@gmail.com, productName=ADIDAS ORIGINAL}]]>
              </value>
            </param>
          </params>
          <exception class="java.lang.AssertionError">
            <message>
              <![CDATA[expected [true] but found [false]]]>
            </message>
            <full-stacktrace>
              <![CDATA[java.lang.AssertionError: expected [true] but found [false]
at org.testng.Assert.fail(Assert.java:99)
at org.testng.Assert.failNotEquals(Assert.java:1037)
at org.testng.Assert.assertTrue(Assert.java:45)
at org.testng.Assert.assertTrue(Assert.java:55)
at vinayakshettypractice.tests.SubmitOrderTest.submitOrder(SubmitOrderTest.java:57)
at java.base/jdk.internal.reflect.DirectMethodHandleAccessor.invoke(DirectMethodHandleAccessor.java:104)
at java.base/java.lang.reflect.Method.invoke(Method.java:578)
at org.testng.internal.MethodInvocationHelper.invokeMethod(MethodInvocationHelper.java:133)
at org.testng.internal.TestInvoker.invokeMethod(TestInvoker.java:598)
at org.testng.internal.TestInvoker.invokeTestMethod(TestInvoker.java:173)
at org.testng.internal.MethodRunner.runInSequence(MethodRunner.java:46)
at org.testng.internal.TestInvoker$MethodInvocationAgent.invoke(TestInvoker.java:824)
at org.testng.internal.TestInvoker.invokeTestMethods(TestInvoker.java:146)
at org.testng.internal.TestMethodWorker.invokeTestMethods(TestMethodWorker.java:146)
at org.testng.internal.TestMethodWorker.run(TestMethodWorker.java:128)
at java.base/java.util.ArrayList.forEach(ArrayList.java:1511)
at org.testng.TestRunner.privateRun(TestRunner.java:794)
at org.testng.TestRunner.run(TestRunner.java:596)
at org.testng.SuiteRunner.runTest(SuiteRunner.java:377)
at org.testng.SuiteRunner.access$000(SuiteRunner.java:28)
at org.testng.SuiteRunner$SuiteWorker.run(SuiteRunner.java:418)
at org.testng.internal.thread.ThreadUtil.lambda$execute$0(ThreadUtil.java:64)
at java.base/java.util.concurrent.FutureTask.run(FutureTask.java:317)
at java.base/java.util.concurrent.ThreadPoolExecutor.runWorker(ThreadPoolExecutor.java:1144)
at java.base/java.util.concurrent.ThreadPoolExecutor$Worker.run(ThreadPoolExecutor.java:642)
at java.base/java.lang.Thread.run(Thread.java:1589)
]]>
            </full-stacktrace>
          </exception> <!-- java.lang.AssertionError -->
          <reporter-output>
          </reporter-output>
        </test-method> <!-- submitOrder -->
        <test-method is-config="true" signature="TearDown()[pri:0, instance:vinayakshettypractice.tests.SubmitOrderTest@221a3fa4]" started-at="2024-02-07T19:34:42 IST" name="TearDown" finished-at="2024-02-07T19:34:42 IST" duration-ms="213" status="PASS">
          <reporter-output>
          </reporter-output>
        </test-method> <!-- TearDown -->
        <test-method is-config="true" signature="launchApplication()[pri:0, instance:vinayakshettypractice.tests.SubmitOrderTest@221a3fa4]" started-at="2024-02-07T19:34:42 IST" name="launchApplication" finished-at="2024-02-07T19:34:46 IST" duration-ms="3460" status="PASS">
          <reporter-output>
          </reporter-output>
        </test-method> <!-- launchApplication -->
        <test-method signature="submitOrder(java.util.HashMap)[pri:0, instance:vinayakshettypractice.tests.SubmitOrderTest@221a3fa4]" started-at="2024-02-07T19:34:46 IST" name="submitOrder" data-provider="getData" finished-at="2024-02-07T19:35:00 IST" duration-ms="13851" status="FAIL">
          <params>
            <param index="0">
              <value>
                <![CDATA[{password=Vinayak@12, email=vinayak01@gmail.com, productName=ZARA COAT 3}]]>
              </value>
            </param>
          </params>
          <exception class="java.lang.AssertionError">
            <message>
              <![CDATA[expected [true] but found [false]]]>
            </message>
            <full-stacktrace>
              <![CDATA[java.lang.AssertionError: expected [true] but found [false]
at org.testng.Assert.fail(Assert.java:99)
at org.testng.Assert.failNotEquals(Assert.java:1037)
at org.testng.Assert.assertTrue(Assert.java:45)
at org.testng.Assert.assertTrue(Assert.java:55)
at vinayakshettypractice.tests.SubmitOrderTest.submitOrder(SubmitOrderTest.java:51)
at java.base/jdk.internal.reflect.DirectMethodHandleAccessor.invoke(DirectMethodHandleAccessor.java:104)
at java.base/java.lang.reflect.Method.invoke(Method.java:578)
at org.testng.internal.MethodInvocationHelper.invokeMethod(MethodInvocationHelper.java:133)
at org.testng.internal.TestInvoker.invokeMethod(TestInvoker.java:598)
at org.testng.internal.TestInvoker.invokeTestMethod(TestInvoker.java:173)
at org.testng.internal.MethodRunner.runInSequence(MethodRunner.java:46)
at org.testng.internal.TestInvoker$MethodInvocationAgent.invoke(TestInvoker.java:824)
at org.testng.internal.TestInvoker.invokeTestMethods(TestInvoker.java:146)
at org.testng.internal.TestMethodWorker.invokeTestMethods(TestMethodWorker.java:146)
at org.testng.internal.TestMethodWorker.run(TestMethodWorker.java:128)
at java.base/java.util.ArrayList.forEach(ArrayList.java:1511)
at org.testng.TestRunner.privateRun(TestRunner.java:794)
at org.testng.TestRunner.run(TestRunner.java:596)
at org.testng.SuiteRunner.runTest(SuiteRunner.java:377)
at org.testng.SuiteRunner.access$000(SuiteRunner.java:28)
at org.testng.SuiteRunner$SuiteWorker.run(SuiteRunner.java:418)
at org.testng.internal.thread.ThreadUtil.lambda$execute$0(ThreadUtil.java:64)
at java.base/java.util.concurrent.FutureTask.run(FutureTask.java:317)
at java.base/java.util.concurrent.ThreadPoolExecutor.runWorker(ThreadPoolExecutor.java:1144)
at java.base/java.util.concurrent.ThreadPoolExecutor$Worker.run(ThreadPoolExecutor.java:642)
at java.base/java.lang.Thread.run(Thread.java:1589)
]]>
            </full-stacktrace>
          </exception> <!-- java.lang.AssertionError -->
          <reporter-output>
          </reporter-output>
        </test-method> <!-- submitOrder -->
        <test-method is-config="true" signature="TearDown()[pri:0, instance:vinayakshettypractice.tests.SubmitOrderTest@221a3fa4]" started-at="2024-02-07T19:35:00 IST" name="TearDown" finished-at="2024-02-07T19:35:00 IST" duration-ms="170" status="PASS">
          <reporter-output>
          </reporter-output>
        </test-method> <!-- TearDown -->
        <test-method signature="OrderHistoryTest()[pri:0, instance:vinayakshettypractice.tests.SubmitOrderTest@221a3fa4]" started-at="2024-02-07T19:35:00 IST" name="OrderHistoryTest" finished-at="2024-02-07T19:35:00 IST" depends-on-methods="vinayakshettypractice.tests.SubmitOrderTest.submitOrder" duration-ms="0" status="SKIP">
          <exception class="java.lang.Throwable">
            <message>
              <![CDATA[Method SubmitOrderTest.OrderHistoryTest()[pri:0, instance:vinayakshettypractice.tests.SubmitOrderTest@221a3fa4] depends on not successfully finished methods]]>
            </message>
            <full-stacktrace>
              <![CDATA[java.lang.Throwable: Method SubmitOrderTest.OrderHistoryTest()[pri:0, instance:vinayakshettypractice.tests.SubmitOrderTest@221a3fa4] depends on not successfully finished methods
at org.testng.internal.TestInvoker.invokeTestMethods(TestInvoker.java:102)
at org.testng.internal.TestMethodWorker.invokeTestMethods(TestMethodWorker.java:146)
at org.testng.internal.TestMethodWorker.run(TestMethodWorker.java:128)
at java.base/java.util.ArrayList.forEach(ArrayList.java:1511)
at org.testng.TestRunner.privateRun(TestRunner.java:794)
at org.testng.TestRunner.run(TestRunner.java:596)
at org.testng.SuiteRunner.runTest(SuiteRunner.java:377)
at org.testng.SuiteRunner.access$000(SuiteRunner.java:28)
at org.testng.SuiteRunner$SuiteWorker.run(SuiteRunner.java:418)
at org.testng.internal.thread.ThreadUtil.lambda$execute$0(ThreadUtil.java:64)
at java.base/java.util.concurrent.FutureTask.run(FutureTask.java:317)
at java.base/java.util.concurrent.ThreadPoolExecutor.runWorker(ThreadPoolExecutor.java:1144)
at java.base/java.util.concurrent.ThreadPoolExecutor$Worker.run(ThreadPoolExecutor.java:642)
at java.base/java.lang.Thread.run(Thread.java:1589)
]]>
            </full-stacktrace>
          </exception> <!-- java.lang.Throwable -->
          <reporter-output>
          </reporter-output>
        </test-method> <!-- OrderHistoryTest -->
      </class> <!-- vinayakshettypractice.tests.SubmitOrderTest -->
    </test> <!-- Submit Order Test -->
    <test started-at="2024-02-07T19:34:20 IST" name="Error Validation Test" finished-at="2024-02-07T19:35:11 IST" duration-ms="51036">
      <class name="vinayakshettypractice.tests.ErrorValidationsTest">
        <test-method is-config="true" signature="launchApplication()[pri:0, instance:vinayakshettypractice.tests.ErrorValidationsTest@333d4a8c]" started-at="2024-02-07T19:34:20 IST" name="launchApplication" finished-at="2024-02-07T19:34:27 IST" duration-ms="6935" status="PASS">
          <reporter-output>
          </reporter-output>
        </test-method> <!-- launchApplication -->
        <test-method retried="true" signature="LoginErrorValidation()[pri:0, instance:vinayakshettypractice.tests.ErrorValidationsTest@333d4a8c]" started-at="2024-02-07T19:34:27 IST" name="LoginErrorValidation" finished-at="2024-02-07T19:34:27 IST" duration-ms="793" status="SKIP">
          <exception class="java.lang.AssertionError">
            <message>
              <![CDATA[expected [Incorrect email or password.] but found [Incorrect email or password]]]>
            </message>
            <full-stacktrace>
              <![CDATA[java.lang.AssertionError: expected [Incorrect email or password.] but found [Incorrect email or password]
at org.testng.Assert.fail(Assert.java:99)
at org.testng.Assert.failNotEquals(Assert.java:1037)
at org.testng.Assert.assertEqualsImpl(Assert.java:140)
at org.testng.Assert.assertEquals(Assert.java:122)
at org.testng.Assert.assertEquals(Assert.java:629)
at org.testng.Assert.assertEquals(Assert.java:639)
at vinayakshettypractice.tests.ErrorValidationsTest.LoginErrorValidation(ErrorValidationsTest.java:38)
at java.base/jdk.internal.reflect.DirectMethodHandleAccessor.invoke(DirectMethodHandleAccessor.java:104)
at java.base/java.lang.reflect.Method.invoke(Method.java:578)
at org.testng.internal.MethodInvocationHelper.invokeMethod(MethodInvocationHelper.java:133)
at org.testng.internal.TestInvoker.invokeMethod(TestInvoker.java:598)
at org.testng.internal.TestInvoker.invokeTestMethod(TestInvoker.java:173)
at org.testng.internal.MethodRunner.runInSequence(MethodRunner.java:46)
at org.testng.internal.TestInvoker$MethodInvocationAgent.invoke(TestInvoker.java:824)
at org.testng.internal.TestInvoker.invokeTestMethods(TestInvoker.java:146)
at org.testng.internal.TestMethodWorker.invokeTestMethods(TestMethodWorker.java:146)
at org.testng.internal.TestMethodWorker.run(TestMethodWorker.java:128)
at java.base/java.util.ArrayList.forEach(ArrayList.java:1511)
at org.testng.TestRunner.privateRun(TestRunner.java:794)
at org.testng.TestRunner.run(TestRunner.java:596)
at org.testng.SuiteRunner.runTest(SuiteRunner.java:377)
at org.testng.SuiteRunner.access$000(SuiteRunner.java:28)
at org.testng.SuiteRunner$SuiteWorker.run(SuiteRunner.java:418)
at org.testng.internal.thread.ThreadUtil.lambda$execute$0(ThreadUtil.java:64)
at java.base/java.util.concurrent.FutureTask.run(FutureTask.java:317)
at java.base/java.util.concurrent.ThreadPoolExecutor.runWorker(ThreadPoolExecutor.java:1144)
at java.base/java.util.concurrent.ThreadPoolExecutor$Worker.run(ThreadPoolExecutor.java:642)
at java.base/java.lang.Thread.run(Thread.java:1589)
]]>
            </full-stacktrace>
          </exception> <!-- java.lang.AssertionError -->
          <reporter-output>
          </reporter-output>
        </test-method> <!-- LoginErrorValidation -->
        <test-method is-config="true" signature="TearDown()[pri:0, instance:vinayakshettypractice.tests.ErrorValidationsTest@333d4a8c]" started-at="2024-02-07T19:34:27 IST" name="TearDown" finished-at="2024-02-07T19:34:28 IST" duration-ms="197" status="PASS">
          <reporter-output>
          </reporter-output>
        </test-method> <!-- TearDown -->
        <test-method is-config="true" signature="launchApplication()[pri:0, instance:vinayakshettypractice.tests.ErrorValidationsTest@333d4a8c]" started-at="2024-02-07T19:34:28 IST" name="launchApplication" finished-at="2024-02-07T19:34:31 IST" duration-ms="3713" status="PASS">
          <reporter-output>
          </reporter-output>
        </test-method> <!-- launchApplication -->
        <test-method signature="LoginErrorValidation()[pri:0, instance:vinayakshettypractice.tests.ErrorValidationsTest@333d4a8c]" started-at="2024-02-07T19:34:31 IST" name="LoginErrorValidation" finished-at="2024-02-07T19:34:32 IST" duration-ms="695" status="FAIL">
          <exception class="java.lang.AssertionError">
            <message>
              <![CDATA[expected [Incorrect email or password.] but found [Incorrect email or password]]]>
            </message>
            <full-stacktrace>
              <![CDATA[java.lang.AssertionError: expected [Incorrect email or password.] but found [Incorrect email or password]
at org.testng.Assert.fail(Assert.java:99)
at org.testng.Assert.failNotEquals(Assert.java:1037)
at org.testng.Assert.assertEqualsImpl(Assert.java:140)
at org.testng.Assert.assertEquals(Assert.java:122)
at org.testng.Assert.assertEquals(Assert.java:629)
at org.testng.Assert.assertEquals(Assert.java:639)
at vinayakshettypractice.tests.ErrorValidationsTest.LoginErrorValidation(ErrorValidationsTest.java:38)
at java.base/jdk.internal.reflect.DirectMethodHandleAccessor.invoke(DirectMethodHandleAccessor.java:104)
at java.base/java.lang.reflect.Method.invoke(Method.java:578)
at org.testng.internal.MethodInvocationHelper.invokeMethod(MethodInvocationHelper.java:133)
at org.testng.internal.TestInvoker.invokeMethod(TestInvoker.java:598)
at org.testng.internal.TestInvoker.retryFailed(TestInvoker.java:213)
at org.testng.internal.MethodRunner.runInSequence(MethodRunner.java:58)
at org.testng.internal.TestInvoker$MethodInvocationAgent.invoke(TestInvoker.java:824)
at org.testng.internal.TestInvoker.invokeTestMethods(TestInvoker.java:146)
at org.testng.internal.TestMethodWorker.invokeTestMethods(TestMethodWorker.java:146)
at org.testng.internal.TestMethodWorker.run(TestMethodWorker.java:128)
at java.base/java.util.ArrayList.forEach(ArrayList.java:1511)
at org.testng.TestRunner.privateRun(TestRunner.java:794)
at org.testng.TestRunner.run(TestRunner.java:596)
at org.testng.SuiteRunner.runTest(SuiteRunner.java:377)
at org.testng.SuiteRunner.access$000(SuiteRunner.java:28)
at org.testng.SuiteRunner$SuiteWorker.run(SuiteRunner.java:418)
at org.testng.internal.thread.ThreadUtil.lambda$execute$0(ThreadUtil.java:64)
at java.base/java.util.concurrent.FutureTask.run(FutureTask.java:317)
at java.base/java.util.concurrent.ThreadPoolExecutor.runWorker(ThreadPoolExecutor.java:1144)
at java.base/java.util.concurrent.ThreadPoolExecutor$Worker.run(ThreadPoolExecutor.java:642)
at java.base/java.lang.Thread.run(Thread.java:1589)
]]>
            </full-stacktrace>
          </exception> <!-- java.lang.AssertionError -->
          <reporter-output>
          </reporter-output>
        </test-method> <!-- LoginErrorValidation -->
        <test-method is-config="true" signature="TearDown()[pri:0, instance:vinayakshettypractice.tests.ErrorValidationsTest@333d4a8c]" started-at="2024-02-07T19:34:33 IST" name="TearDown" finished-at="2024-02-07T19:34:33 IST" duration-ms="122" status="PASS">
          <reporter-output>
          </reporter-output>
        </test-method> <!-- TearDown -->
        <test-method is-config="true" signature="launchApplication()[pri:0, instance:vinayakshettypractice.tests.ErrorValidationsTest@333d4a8c]" started-at="2024-02-07T19:34:33 IST" name="launchApplication" finished-at="2024-02-07T19:34:38 IST" duration-ms="5041" status="PASS">
          <reporter-output>
          </reporter-output>
        </test-method> <!-- launchApplication -->
        <test-method retried="true" signature="ProductErrorValidation()[pri:0, instance:vinayakshettypractice.tests.ErrorValidationsTest@333d4a8c]" started-at="2024-02-07T19:34:38 IST" name="ProductErrorValidation" finished-at="2024-02-07T19:34:52 IST" duration-ms="14059" status="SKIP">
          <exception class="java.lang.AssertionError">
            <message>
              <![CDATA[expected [true] but found [false]]]>
            </message>
            <full-stacktrace>
              <![CDATA[java.lang.AssertionError: expected [true] but found [false]
at org.testng.Assert.fail(Assert.java:99)
at org.testng.Assert.failNotEquals(Assert.java:1037)
at org.testng.Assert.assertTrue(Assert.java:45)
at org.testng.Assert.assertTrue(Assert.java:55)
at vinayakshettypractice.tests.ErrorValidationsTest.ProductErrorValidation(ErrorValidationsTest.java:55)
at java.base/jdk.internal.reflect.DirectMethodHandleAccessor.invoke(DirectMethodHandleAccessor.java:104)
at java.base/java.lang.reflect.Method.invoke(Method.java:578)
at org.testng.internal.MethodInvocationHelper.invokeMethod(MethodInvocationHelper.java:133)
at org.testng.internal.TestInvoker.invokeMethod(TestInvoker.java:598)
at org.testng.internal.TestInvoker.invokeTestMethod(TestInvoker.java:173)
at org.testng.internal.MethodRunner.runInSequence(MethodRunner.java:46)
at org.testng.internal.TestInvoker$MethodInvocationAgent.invoke(TestInvoker.java:824)
at org.testng.internal.TestInvoker.invokeTestMethods(TestInvoker.java:146)
at org.testng.internal.TestMethodWorker.invokeTestMethods(TestMethodWorker.java:146)
at org.testng.internal.TestMethodWorker.run(TestMethodWorker.java:128)
at java.base/java.util.ArrayList.forEach(ArrayList.java:1511)
at org.testng.TestRunner.privateRun(TestRunner.java:794)
at org.testng.TestRunner.run(TestRunner.java:596)
at org.testng.SuiteRunner.runTest(SuiteRunner.java:377)
at org.testng.SuiteRunner.access$000(SuiteRunner.java:28)
at org.testng.SuiteRunner$SuiteWorker.run(SuiteRunner.java:418)
at org.testng.internal.thread.ThreadUtil.lambda$execute$0(ThreadUtil.java:64)
at java.base/java.util.concurrent.FutureTask.run(FutureTask.java:317)
at java.base/java.util.concurrent.ThreadPoolExecutor.runWorker(ThreadPoolExecutor.java:1144)
at java.base/java.util.concurrent.ThreadPoolExecutor$Worker.run(ThreadPoolExecutor.java:642)
at java.base/java.lang.Thread.run(Thread.java:1589)
]]>
            </full-stacktrace>
          </exception> <!-- java.lang.AssertionError -->
          <reporter-output>
          </reporter-output>
        </test-method> <!-- ProductErrorValidation -->
        <test-method is-config="true" signature="TearDown()[pri:0, instance:vinayakshettypractice.tests.ErrorValidationsTest@333d4a8c]" started-at="2024-02-07T19:34:52 IST" name="TearDown" finished-at="2024-02-07T19:34:53 IST" duration-ms="167" status="PASS">
          <reporter-output>
          </reporter-output>
        </test-method> <!-- TearDown -->
        <test-method is-config="true" signature="launchApplication()[pri:0, instance:vinayakshettypractice.tests.ErrorValidationsTest@333d4a8c]" started-at="2024-02-07T19:34:53 IST" name="launchApplication" finished-at="2024-02-07T19:34:57 IST" duration-ms="4110" status="PASS">
          <reporter-output>
          </reporter-output>
        </test-method> <!-- launchApplication -->
        <test-method signature="ProductErrorValidation()[pri:0, instance:vinayakshettypractice.tests.ErrorValidationsTest@333d4a8c]" started-at="2024-02-07T19:34:57 IST" name="ProductErrorValidation" finished-at="2024-02-07T19:35:10 IST" duration-ms="13766" status="PASS">
          <reporter-output>
          </reporter-output>
        </test-method> <!-- ProductErrorValidation -->
        <test-method is-config="true" signature="TearDown()[pri:0, instance:vinayakshettypractice.tests.ErrorValidationsTest@333d4a8c]" started-at="2024-02-07T19:35:10 IST" name="TearDown" finished-at="2024-02-07T19:35:11 IST" duration-ms="194" status="PASS">
          <reporter-output>
          </reporter-output>
        </test-method> <!-- TearDown -->
      </class> <!-- vinayakshettypractice.tests.ErrorValidationsTest -->
    </test> <!-- Error Validation Test -->
  </suite> <!-- Suite -->
</testng-results>
